Workbook

Sheet Wage Percentage
B1: RESTAURANT WAGE % CALCULATION SHEET
A2: LOCATION: THE ROCKS | B2: WEEK ENDING: | C2: 07/09/2026
A3: Average Hourly Rate = $ | B3: HOURS
A4: Ordinary 1x | B4: ='Costing sheet'!D51 | C4: ='Costing sheet'!E51
A5: Saturday 1.25x | B5: ='Costing sheet'!F51 | C5: ='Costing sheet'!G51
A6: Sunday 1.5x | B6: ='Costing sheet'!H51 | C6: ='Costing sheet'!I51 | Z6: 4.6
A7: Over Time 1.5x | B7: ='Costing sheet'!J51 | C7: ='Costing sheet'!K51
A8: Over Time 1.75x | B8: ='Costing sheet'!L51 | C8: ='Costing sheet'!M51
A9: Saturday / Milko | B9: ='Costing sheet'!N51 | C9: ='Costing sheet'!O51
A10: Over Time 2x | B10: ='Costing sheet'!P51 | C10: ='Costing sheet'!Q51
A11: P/Holiday 2.25x / 2.5x | B11: ='Costing sheet'!R51+'Costing sheet'!T51 | C11: ='Costing sheet'!S51+'Costing sheet'!U51
A12: Sick Leave | B12: ='Costing sheet'!V51 | C12: ='Costing sheet'!W51
A13: Split / Laundry / clothing Allowances | C13: ='Costing sheet'!Z51+'Costing sheet'!AF51
A14: Penalty Allowances 10-12am / 12-6am | C14: =SUM('Costing sheet'!AC51,'Costing sheet'!AE51)
A15: Supervisor / Public Holiday Allowances | C15: ='Costing sheet'!AA51
A16: Paid Annual Leave | B16: ='Costing sheet'!X51 | C16: ='Costing sheet'!Y51
A17: TOTAL | B17: =SUM(B4:B16) | C17: =SUM(C4:C16)
A19: Cleaning
A20: Promotions
A21: Annual Leave/termination pay | B21: =B16 | C21: =C16 | G21: `
A22: Transfer In from (BH) | B22: =Transfers!AA77 | C22: =Transfers!AB77
A23: Transfer IN from (NM) | B23: =Transfers!AA64 | C23: =Transfers!AB64
A24: Transfer IN from (DSQ) | B24: =Transfers!AA51 | C24: =Transfers!AB51
A25: Transfer OUT to (DSQ) | B25: =Transfers!AA12 | C25: =Transfers!AB12
A26: Transfer OUT to (BH) | Z26: 4.6
A27: Transfer OUT to (BH) | B27: =Transfers!AA23 | C27: =Transfers!AB23 | Z27: 4.6
A28: Transfer OUT to (NM) | B28: =Transfers!AA33 | C28: =Transfers!AB33 | Z28: 4.6
A30: Superannuation | B30: =B17*0.12 | C30: =C17*0.12
A31: Leave Liability | B31: =B17*7.69/100 | C31: =C17*7.69/100
A32: TOTAL WAGES | B32: =B17+B22+B23+B24-B25-B26-B27-B28+B31-B21+B18 | C32: =C17+C22+C23+C24-C25-C26-C27-C28+C30+C31-C21+C18
A34: Sick Leave | B34: =B12 | C34: =C12
A35: Leave Liability | B35: =B31 | C35: =C31
A36: Training | C36: 0
A37: Total Hours For Productivity | B37: =B32-(B34+B35+B36)
A38: GROSS TOTAL | B38: 117324.85
A39: Nett SALES (-GST) | B39: =B38/1.1
A40: CUSTOMERS | B40: 4500 | R40: =78875-68645.72
A41: WAGE % TO GROSS TOTAL | B41: =C32/B38
A42: WAGE % TO NETT TOTAL | B42: =C32/B39
A43: PRODUCTIVITY | B43: =B40/B37
...

Sheet Adjustments
C1: PAYROLL ADJUSTMENT FORM
A2: POTR | B2: WEEK ENDING: | C2: ='Wage Percentage'!C2
A3: NUMBER | B3: NAME | C3: ADJUSTMENT TO BE MADE
B4: TERMINATE
I9: 0
B10: NEW STARTER
B21: BACKPAY
B28: CHANGE TO CASUAL

Sheet Costing sheet
A1: ='Wage Percentage'!C2 | D1: THE ROCKS
J2: HOURLY COSTING | Z2: Allowances | AC2: 2.95 | AE2: 4.42 | AF2: 11.2
A3: EMPLOYEE | C3: RATE | D3: 1 | E3: $ | F3: 1.25 | G3: $ | H3: 1.5 | I3: $ | J3: 1.5 | K3: $ | L3: 1.75 | M3: $ | N3: 2 | O3: $ | P3: 2 | Q3: $ | R3: 2.25 | S3: $ | T3: 2.5 | U3: $ | V3: Sick | W3: $ | X3: Holiday | Y3: $ | Z3: Laundry | AA3: Superv. | AB3: Penalty | AC3: $ | AE3: $ | AF3: Split | AG3: TOTAL | AH3: TOTAL
D4: ORD | F4: SAT | H4: SUN | J4: O/T | L4: O/T | N4: sat2-7am | P4: O/T | R4: (PH) | T4: (PH)
F5: ORD CAS | H5: SAT CAS | L5: SUN CAS | T5: CAS
A6: AKTER, Nasrin | B6: 2 | C6: 27.08 | D6: 7.5 | E6: =C6*D6 | F6: 10 | G6: =C6*1.25*F6 | H6: 5 | I6: =C6*1.5*H6 | K6: =C6*1.5*J6 | M6: =C6*1.75*L6 | O6: =C6*2*N6 | Q6: =C6*2*P6 | S6: =C6*2.25*R6 | W6: =C6*V6 | Y6: =C6*X6 | Z6: 6.9 | AC6: =AB6*2.95 | AE6: =AD6*4.42 | AF6: =11.2*2 | AG6: =D6+F6+H6+J6+L6+P6+R6+V6+X6+N6 | AH6: =E6+G6+I6+K6+M6+Q6+S6+Z6+AA6+W6+Y6+AC6+AE6+AF6+O6+U6
A7: BANTHIA, Jiya | B7: 2 | C7: 27.08 | D7: 10 | E7: =C7*D7 | F7: 7.5 | G7: =C7*1.25*F7 | H7: 8.75 | I7: =C7*1.5*H7 | K7: =C7*1.5*J7 | M7: =C7*1.75*L7 | O7: =C7*2*N7 | Q7: =C7*2*P7 | S7: =C7*2.25*R7 | U7: =C7*2.5*T7 | W7: =C7*V7 | Y7: =C7*X7 | Z7: 6.9 | AB7: 2 | AC7: =AB7*2.95 | AE7: =AD7*4.42 | AF7: 11.2 | AG7: =D7+F7+H7+J7+L7+P7+R7+V7+X7+N7+T7 | AH7: =E7+G7+I7+K7+M7+Q7+S7+Z7+AA7+W7+Y7+AC7+AE7+AF7+O7
A8: BHATTARAI, Abisekh | B8: 2 | C8: 27.08 | D8: 12.5 | E8: =C8*D8 | F8: 7.25 | G8: =C8*1.25*F8 | H8: 0.25 | I8: =C8*1.5*H8 | K8: =C8*1.5*J8 | M8: =C8*1.75*L8 | O8: =C8*2*N8 | Q8: =C8*2*P8 | S8: =C8*2.25*R8 | U8: =C8*2.5*T8 | V8: 5 | W8: =C8*V8 | Y8: =C8*X8 | Z8: 6.9 | AB8: 2 | AC8: =AB8*2.95 | AD8: 1 | AE8: =AD8*4.42 | AG8: =D8+F8+H8+J8+L8+P8+R8+V8+X8+N8+T8 | AH8: =E8+G8+I8+K8+M8+Q8+S8+Z8+AA8+W8+Y8+AC8+AE8+AF8+O8
A9: B.K, Sanjay | B9: 2 | C9: 27.08 | D9: 17.5 | E9: =C9*D9 | F9: 9.5 | G9: =C9*1.25*F9 | H9: 9.5 | I9: =C9*1.5*H9 | K9: =C9*1.5*J9 | M9: =C9*1.75*L9 | O9: =C9*2*N9 | Q9: =C9*2*P9 | S9: =C9*2.25*R9 | W9: =C9*V9 | Y9: =C9*X9 | Z9: 6.9 | AB9: 4 | AC9: =AB9*2.95 | AD9: 1 | AE9: =AD9*4.42 | AG9: =D9+F9+H9+J9+L9+P9+R9+V9+X9+N9 | AH9: =E9+G9+I9+K9+M9+Q9+S9+Z9+AA9+W9+Y9+AC9+AE9+AF9+O9
A10: BOSC, Melissa | B10: 2 | C10: 27.08 | E10: =C10*D10 | G10: =C10*1.25*F10 | I10: =C10*1.5*H10 | K10: =C10*1.5*J10 | M10: =C10*1.75*L10 | O10: =C10*2*N10 | Q10: =C10*2*P10 | S10: =C10*2.25*R10 | W10: =C10*V10 | Y10: =C10*X10 | AC10: =AB10*2.95 | AE10: =AD10*4.42 | AG10: =D10+F10+H10+J10+L10+P10+R10+V10+X10+N10 | AH10: =E10+G10+I10+K10+M10+Q10+S10+Z10+AA10+W10+Y10+AC10+AE10+AF10+O10
A11: BUTTERS, Gary | B11: SUP | C11: 29.45 | D11: 16 | E11: =C11*D11 | F11: 7.5 | G11: =C11*1.25*F11 | H11: 8.5 | I11: =C11*1.5*H11 | K11: =C11*1.5*J11 | M11: =C11*1.75*L11 | O11: =C11*2*N11 | Q11: =C11*2*P11 | S11: =C11*2.25*R11 | W11: =C11*V11 | X11: 6 | Y11: =C11*X11 | Z11: 6.9 | AA11: 30 | AB11: 2 | AC11: =AB11*2.95 | AE11: =AD11*4.42 | AG11: =D11+F11+H11+J11+L11+P11+R11+V11+X11+N11 | AH11: =E11+G11+I11+K11+M11+Q11+S11+Z11+AA11+W11+Y11+AC11+AE11+AF11+O11
A12: CHAULAGAIN, Unisha | B12: 2 | C12: 27.08 | D12: 15 | E12: =C12*D12 | F12: 8 | G12: =C12*1.25*F12 | H12: 9.5 | I12: =C12*1.5*H12 | K12: =C12*1.5*J12 | M12: =C12*1.75*L12 | N12: 0.5 | O12: =C12*2*N12 | Q12: =C12*2*P12 | S12: =C12*2.25*R12 | U12: =C12*2.5*T12 | W12: =C12*V12 | Y12: =C12*X12 | Z12: 6.9 | AB12: 2 | AC12: =AB12*2.95 | AD12: 1 | AE12: =AD12*4.42 | AF12: 11.2 | AG12: =D12+F12+H12+J12+L12+P12+R12+V12+X12+N12+T12 | AH12: =E12+G12+I12+K12+M12+Q12+S12+Z12+AA12+W12+Y12+AC12+AE12+AF12+O12
A13: DALSANIYA, Vismay | B13: 2 | C13: 27.97 | D13: 23 | E13: =C13*D13 | F13: 8 | G13: =C13*1.25*F13 | H13: 7.5 | I13: =C13*1.5*H13 | J13: 1 | K13: =C13*1.5*J13 | M13: =C13*1.75*L13 | O13: =C13*2*N13 | Q13: =C13*2*P13 | S13: =C13*2.25*R13 | W13: =C13*V13 | Y13: =C13*X13 | Z13: 6.9 | AB13: 2 | AC13: =AB13*2.95 | AD13: 1 | AE13: =AD13*4.42 | AG13: =D13+F13+H13+J13+L13+P13+R13+V13+X13+N13 | AH13: =E13+G13+I13+K13+M13+Q13+S13+Z13+AA13+W13+Y13+AC13+AE13+AF13+O13
A14: DUTTA Pinake | B14: SAL | C14: 45.55 | D14: 41.75 | E14: =C14*D14 | G14: =C14*1.25*F14 | I14: =C14*1.5*H14 | K14: =C14*1.5*J14 | M14: =C14*1.75*L14 | O14: =C14*2*N14 | Q14: =C14*2*P14 | S14: =C14*2.25*R14 | W14: =C14*V14 | Y14: =C14*X14 | Z14: 15 | AC14: =AB14*2.95 | AE14: =AD14*4.42 | AG14: =(D14+F14+H14+J14+L14+P14+R14+V14+X14+N14)+(J15+L15+P15+R15) | AH14: =(E14+G14+I14+K14+M14+Q14+S14+Z14+AA14+W14+Y14+AC14+AE14+AF14+O14)+(K15+M15+Q15+S15)
C15: 31.3 | K15: =C15*1.5*J15 | M15: =C15*1.75*L15 | Q15: =C15*2*P15 | S15: =C15*2.25*R15 | AC15: =AB15*2.95 | AE15: =AD15*4.42
A16: FAN, Yong (Richard) | B16: SUP | C16: 29.45 | E16: =C16*D16 | F16: 2 | G16: =C16*1.25*F16 | H16: 3.5 | I16: =C16*1.5*H16 | K16: =C16*1.5*J16 | M16: =C16*1.75*L16 | O16: =C16*2*N16 | Q16: =C16*2*P16 | S16: =C16*2.25*R16 | U16: =C16*2.5*T16 | Z16: 4.6 | AC16: =AB16*2.95 | AE16: =AD16*4.42 | AG16: =D16+F16+H16+J16+L16+P16+R16+V16+X16+N16+T16 | AH16: =E16+G16+I16+K16+M16+Q16+S16+Z16+AA16+W16+Y16+AC16+AE16+AF16+O16+U16
A17: FEIGE, Oliver | B17: CAS | C17: 18.51 | G17: =C17*1.25*F17 | I17: =C17*1.5*H17 | K17: =C17*1.5*J17 | M17: =C17*1.75*L17 | O17: =C17*2*N17 | Q17: =C17*2*P17 | U17: =C17*2.5*T17 | AC17: =AB17*2.95 | AE17: =AD17*4.42 | AG17: =D17+F17+H17+J17+L17+P17+R17+V17+X17+N17+T17 | AH17: =E17+G17+I17+K17+M17+Q17+S17+Z17+AA17+W17+Y17+AC17+AE17+AF17+O17+U17
A18: FERNANDES, Delisha | B18: SAL | C18: 39.48 | D18: 22 | E18: =C18*D18 | G18: =C18*1.25*F18 | I18: =C18*1.5*H18 | K18: =C18*1.5*J18 | M18: =C18*1.75*L18 | O18: =C18*2*N18 | Q18: =C18*2*P18 | S18: =C18*2.25*R18 | W18: =C18*V18 | X18: 16 | Y18: =C18*X18 | Z18: 15 | AC18: =AB18*2.95 | AE18: =AD18*4.42 | AG18: =(D18+F18+H18+J18+L18+P18+R18+V18+X18+N18)+(J19+L19+P19+R19) | AH18: =(E18+G18+I18+K18+M18+Q18+S18+Z18+AA18+W18+Y18+AC18+AE18+AF18+O18)+(K19+M19+Q19+S19)
C19: 29.45 | K19: =C19*1.5*J19 | M19: =C19*1.75*L19 | Q19: =C19*2*P19 | S19: =C19*2.25*R19 | AC19: =AB19*2.95 | AE19: =AD19*4.42
A20: GAUCHAN, Bibek | B20: SAL | C20: 37.45 | E20: =C20*D20 | G20: =C20*1.25*F20 | I20: =C20*1.5*H20 | K20: =C20*1.5*J20 | M20: =C20*1.75*L20 | O20: =C20*2*N20 | Q20: =C20*2*P20 | S20: =C20*2.25*R20 | W20: =C20*V20 | X20: 38 | Y20: =C20*X20 | AC20: =AB20*2.95 | AE20: =AD20*4.42 | AG20: =(D20+F20+H20+J20+L20+P20+R20+V20+X20+N20)+(J21+L21+P21+R21) | AH20: =(E20+G20+I20+K20+M20+Q20+S20+Z20+AA20+W20+Y20+AC20+AE20+AF20+O20)+(K21+M21+Q21+S21)
C21: 29.45 | K21: =C21*1.5*J21 | M21: =C21*1.75*L21 | Q21: =C21*2*P21 | S21: =C21*2.25*R21 | AC21: =AB21*2.95 | AE21: =AD21*4.42
A22: GAUCHAN, Roshani | B22: SAL | C22: 37.45 | D22: 38.25 | E22: =C22*D22 | G22: =C22*1.25*F22 | I22: =C22*1.5*H22 | K22: =C22*1.5*J22 | M22: =C22*1.75*L22 | O22: =C22*2*N22 | Q22: =C22*2*P22 | S22: =C22*2.25*R22 | W22: =C22*V22 | Y22: =C22*X22 | Z22: 15 | AC22: =AB22*2.95 | AE22: =AD22*4.42 | AG22: =(D22+F22+H22+J22+L22+P22+R22+V22+X22+N22)+(J23+L23+P23+R23) | AH22: =(E22+G22+I22+K22+M22+Q22+S22+Z22+AA22+W22+Y22+AC22+AE22+AF22+O22)+(K23+M23+Q23+S23)
C23: 29.45 | K23: =C23*1.5*J23 | M23: =C23*1.75*L23 | Q23: =C23*2*P23 | S23: =C23*2.25*R23 | W23: =C23*V23 | AC23: =AB23*2.95 | AE23: =AD23*4.42
A24: JAHAN, Nusrat | B24: 2 | C24: 27.08 | D24: 17.5 | E24: =C24*D24 | F24: 7.5 | G24: =C24*1.25*F24 | H24: 7.5 | I24: =C24*1.5*H24 | K24: =C24*1.5*J24 | L24: 2 | M24: =C24*1.75*L24 | O24: =C24*2*N24 | P24: 0.75 | Q24: =C24*2*P24 | S24: =C24*2.25*R24 | U24: =C24*2.5*T24 | W24: =C24*V24 | Y24: =C24*X24 | Z24: 6.9 | AC24: =AB24*2.95 | AE24: =AD24*4.42 | AF24: 22.4 | AG24: =D24+F24+H24+J24+L24+P24+R24+V24+X24+N24+T24 | AH24: =E24+G24+I24+K24+M24+Q24+S24+Z24+AA24+W24+Y24+AC24+AE24+AF24+O24
A25: KC Anisha | B25: 2 | C25: 27.97 | D25: 21 | E25: =C25*D25 | F25: 8 | G25: =C25*1.25*F25 | H25: 8 | I25: =C25*1.5*H25 | K25: =C25*1.5*J25 | M25: =C25*1.75*L25 | O25: =C25*2*N25 | Q25: =C25*2*P25 | S25: =C25*2.25*R25 | W25: =C25*V25 | Y25: =C25*X25 | Z25: 6.9 | AB25: 2 | AC25: =AB25*2.95 | AD25: 1 | AE25: =AD25*4.42 | AG25: =D25+F25+H25+J25+L25+P25+R25+V25+X25+N25 | AH25: =E25+G25+I25+K25+M25+Q25+S25+Z25+AA25+W25+Y25+AC25+AE25+AF25+O25
A26: KC Sulav | B26: SAL | C26: 37.45 | E26: =C26*D26 | G26: =C26*1.25*F26 | I26: =C26*1.5*H26 | K26: =C26*1.5*J26 | M26: =C26*1.75*L26 | O26: =C26*2*N26 | Q26: =C26*2*P26 | S26: =C26*2.25*R26 | W26: =C26*V26 | X26: 38 | Y26: =C26*X26 | AC26: =AB26*2.95 | AE26: =AD26*4.42 | AG26: =(D26+F26+H26+J26+L26+P26+R26+V26+X26+N26)+(J27+L27+P27+R27) | AH26: =(E26+G26+I26+K26+M26+Q26+S26+Z26+AA26+W26+Y26+AC26+AE26+AF26+O26)+(K27+M27+Q27+S27)
C27: 29.45 | K27: =C27*1.5*J27 | M27: =C27*1.75*L27 | Q27: =C27*2*P27 | S27: =C27*2.25*R27 | AC27: =AB27*2.95 | AE27: =AD27*4.42
A28: KHATRI, Sanjay | B28: SAL | C28: 37.45 | D28: 36.5 | E28: =C28*D28 | G28: =C28*1.25*F28 | I28: =C28*1.5*H28 | K28: =C28*1.5*J28 | M28: =C28*1.75*L28 | O28: =C28*2*N28 | Q28: =C28*2*P28 | S28: =C28*2.25*R28 | V28: 1.5 | W28: =C28*V28 | Y28: =C28*X28 | Z28: 15 | AC28: =AB28*2.95 | AE28: =AD28*4.42 | AG28: =(D28+F28+H28+J28+L28+P28+R28+V28+X28+N28)+(J29+L29+P29+R29) | AH28: =(E28+G28+I28+K28+M28+Q28+S28+Z28+AA28+W28+Y28+AC28+AE28+AF28+O28)+(K29+M29+Q29+S29)
C29: 29.45 | K29: =C29*1.5*J29 | M29: =C29*1.75*L29 | Q29: =C29*2*P29 | S29: =C29*2.25*R29 | AC29: =AB29*2.95 | AE29: =AD29*4.42
A30: MAHMUD M M Ferdous | B30: SAL | C30: 37.45 | D30: 37.5 | E30: =C30*D30 | G30: =C30*1.25*F30 | I30: =C30*1.5*H30 | K30: =C30*1.5*J30 | M30: =C30*1.75*L30 | O30: =C30*2*N30 | Q30: =C30*2*P30 | S30: =C30*2.25*R30 | W30: =C30*V30 | X30: 0.5 | Y30: =C30*X30 | Z30: 15 | AC30: =AB30*2.95 | AE30: =AD30*4.42 | AG30: =(D30+F30+H30+J30+L30+P30+R30+V30+X30+N30)+(J31+L31+P31+R31) | AH30: =(E30+G30+I30+K30+M30+Q30+S30+Z30+AA30+W30+Y30+AC30+AE30+AF30+O30)+(K31+M31+Q31+S31)
C31: 29.45 | K31: =C31*1.5*J31 | M31: =C31*1.75*L31 | Q31: =C31*2*P31 | S31: =C31*2.25*R31 | AC31: =AB31*2.95 | AE31: =AD31*4.42
A32: MAJOHR, Jolie | B32: 2 | C32: 27.08 | E32: =C32*D32 | G32: =C32*1.25*F32 | H32: 5 | I32: =C32*1.5*H32 | K32: =C32*1.5*J32 | L32: 7 | M32: =C32*1.75*L32 | O32: =C32*2*N32 | Q32: =C32*2*P32 | S32: =C32*2.25*R32 | W32: =C32*V32 | Y32: =C32*X32 | Z32: 4.6 | AC32: =AB32*2.95 | AE32: =AD32*4.42 | AG32: =D32+F32+H32+J32+L32+P32+R32+V32+X32+N32 | AH32: =E32+G32+I32+K32+M32+Q32+S32+Z32+AA32+W32+Y32+AC32+AE32+AF32+O32+U32
A33: MALLA, Kajal | B33: 2 | C33: 27.08 | D33: 20.5 | E33: =C33*D33 | F33: 7.5 | G33: =C33*1.25*F33 | H33: 5 | I33: =C33*1.5*H33 | K33: =C33*1.5*J33 | M33: =C33*1.75*L33 | O33: =C33*2*N33 | Q33: =C33*2*P33 | S33: =C33*2.25*R33 | W33: =C33*V33 | Y33: =C33*X33 | Z33: 6.9 | AC33: =AB33*2.95 | AE33: =AD33*4.42 | AF33: 11.2 | AG33: =D33+F33+H33+J33+L33+P33+R33+V33+X33+N33 | AH33: =E33+G33+I33+K33+M33+Q33+S33+Z33+AA33+W33+Y33+AC33+AE33+AF33+O33
A34: RAHMAN, Mahinur | B34: 2 | C34: 27.08 | E34: =C34*D34 | G34: =C34*1.25*F34 | I34: =C34*1.5*H34 | K34: =C34*1.5*J34 | M34: =C34*1.75*L34 | O34: =C34*2*N34 | Q34: =C34*2*P34 | S34: =C34*2.25*R34 | U34: =C34*2.5*T34 | W34: =C34*V34 | Y34: =C34*X34 | AC34: =AB34*2.95 | AE34: =AD34*4.42 | AG34: =D34+F34+H34+J34+L34+P34+R34+T34+X34+N34 | AH34: =E34+G34+I34+K34+M34+Q34+S34+Z34+AA34+U34+Y34+AC34+AE34+AF34+O34
A35: RANA, Royal | B35: 2 | C35: 27.08 | D35: 21.5 | E35: =C35*D35 | F35: 5 | G35: =C35*1.25*F35 | I35: =C35*1.5*H35 | K35: =C35*1.5*J35 | M35: =C35*1.75*L35 | O35: =C35*2*N35 | Q35: =C35*2*P35 | S35: =C35*2.25*R35 | U35: =C35*2.5*T35 | W35: =C35*V35 | Y35: =C35*X35 | Z35: 6.9 | AB35: 4 | AC35: =AB35*2.95 | AD35: 2 | AE35: =AD35*4.42 | AG35: =D35+F35+H35+J35+L35+P35+R35+V35+X35+N35+T35 | AH35: =E35+G35+I35+K35+M35+Q35+S35+Z35+AA35+W35+Y35+AC35+AE35+AF35+O35
A36: SAHA, Oyndrilla | B36: SUP | C36: 29.45 | D36: 11 | E36: =C36*D36 | F36: 5 | G36: =C36*1.25*F36 | H36: 7.5 | I36: =C36*1.5*H36 | K36: =C36*1.5*J36 | M36: =C36*1.75*L36 | O36: =C36*2*N36 | Q36: =C36*2*P36 | S36: =C36*2.25*R36 | W36: =C36*V36 | Y36: =C36*X36 | Z36: 6.9 | AC36: =AB36*2.95 | AE36: =AD36*4.42 | AG36: =D36+F36+H36+J36+L36+P36+R36+V36+X36+N36 | AH36: =E36+G36+I36+K36+M36+Q36+S36+Z36+AA36+W36+Y36+AC36+AE36+AF36+O36
A37: SAIYED, Wasim | B37: SAL | C37: 36.81 | D37: 30.25 | E37: =C37*D37 | G37: =C37*1.25*F37 | I37: =C37*1.5*H37 | K37: =C37*1.5*J37 | M37: =C37*1.75*L37 | O37: =C37*2*N37 | Q37: =C37*2*P37 | S37: =C37*2.25*R37 | W37: =C37*V37 | X37: 7.75 | Y37: =C37*X37 | Z37: 15 | AC37: =AB37*2.95 | AE37: =AD37*4.42 | AG37: =(D37+F37+H37+J37+L37+P37+R37+V37+X37+N37)+(J38+L38+P38+R38) | AH37: =(E37+G37+I37+K37+M37+Q37+S37+Z37+AA37+W37+Y37+AC37+AE37+AF37+O37)+(K38+M38+Q38+S38)
C38: 29.45 | K38: =C38*1.5*J38 | M38: =C38*1.75*L38 | Q38: =C38*2*P38 | S38: =C38*2.25*R38 | AC38: =AB38*2.95 | AE38: =AD38*4.42
A39: SAMIT, Satwat Hossain | B39: 2 | C39: 27.97 | D39: 25.5 | E39: =C39*D39 | F39: 5 | G39: =C39*1.25*F39 | H39: 7.5 | I39: =C39*1.5*H39 | K39: =C39*1.5*J39 | M39: =C39*1.75*L39 | O39: =C39*2*N39 | P39: 0.25 | Q39: =C39*2*P39 | S39: =C39*2.25*R39 | W39: =C39*V39 | Y39: =C39*X39 | Z39: 6.9 | AC39: =AB39*2.95 | AE39: =AD39*4.42 | AG39: =D39+F39+H39+J39+L39+P39+R39+V39+X39+N39 | AH39: =E39+G39+I39+K39+M39+Q39+S39+Z39+AA39+W39+Y39+AC39+AE39+AF39+O39
A40: SHIWAKOTI, Rojal | B40: SUP | C40: 29.85 | D40: 7 | E40: =C40*D40 | F40: 7.5 | G40: =C40*1.25*F40 | H40: 10 | I40: =C40*1.5*H40 | K40: =C40*1.5*J40 | M40: =C40*1.75*L40 | O40: =C40*2*N40 | P40: 0.25 | Q40: =C40*2*P40 | S40: =C40*2.25*R40 | W40: =C40*V40 | Y40: =C40*X40 | Z40: 6.9 | AA40: 15 | AB40: 2 | AC40: =AB40*2.95 | AD40: 1 | AE40: =AD40*4.42 | AF40: 11.2 | AG40: =D40+F40+H40+J40+L40+P40+R40+V40+X40+N40 | AH40: =E40+G40+I40+K40+M40+Q40+S40+Z40+AA40+W40+Y40+AC40+AE40+AF40+O40
...

Sheet Data Sheet
A1: POTR - THE ROCKS | B1: ='Wage Percentage'!C2
A2: EMPLOYEE | C2: SAT | D2: SUN | E2: O/Time | F2: O/Time | G2: Sat Milko 2.0 | H2: O/Time | I2: P/Hol | J2: P/Hol | K2: Sick | L2: Annual | M2: LAUN | N2: SUPER | O2: PEN | P2: PEN | Q2: Split | R2: TOTAL
A3: NAME | B3: ORD | C3: 1.25 | D3: 1.5 | E3: 1.5 | F3: 1.75 | H3: 2 | I3: 2.25 | J3: 2.5 | K3: Leave | L3: Leave | M3: Allow | N3: Allow | O3: 10-12am | P3: 12-6am | Q3: Allow
C4: ORD CAS | D4: SAT CAS | F4: SUN CAS | J4: CAS | Q4: 11.2
A5: AKTER, Nasrin | B5: 750 | C5: 1000 | D5: 500 | M5: 3 | Q5: 22.4 | R5: =B5+C5+D5+E5+F5+G5+H5+I5+K5+L5+J5
A6: BANTHIA, Jiya | B6: 1000 | C6: 750 | D6: 875 | M6: 3 | O6: 2 | Q6: 11.2 | R6: =B6+C6+D6+E6+F6+G6+H6+I6+K6+L6+J6
A7: BHATTARAI, Abisekh | B7: 1250 | C7: 725 | D7: 25 | K7: 500 | M7: 3 | O7: 2 | P7: 1 | R7: =B7+C7+D7+E7+F7+G7+H7+I7+K7+L7+J7
A8: B.K, Sanjay | B8: 1750 | C8: 950 | D8: 950 | M8: 3 | O8: 4 | P8: 1 | R8: =B8+C8+D8+E8+F8+G8+H8+I8+K8+L8
A9: BOSC, Melissa | R9: =B9+C9+D9+E9+F9+G9+H9+I9+K9+L9+J9
A10: BUTTERS, Gary | B10: 1600 | C10: 750 | D10: 850 | L10: 600 | M10: 3 | N10: 30 | O10: 2 | R10: =B10+C10+D10+E10+F10+G10+H10+I10+K10+L10
A11: CHAULAGAIN, Unisha | B11: 1500 | C11: 800 | D11: 950 | G11: 50 | M11: 3 | O11: 2 | P11: 1 | Q11: 11.2 | R11: =B11+C11+D11+E11+F11+G11+H11+I11+K11+L11+J11
A12: DALSANIYA, Vismay | B12: 2300 | C12: 800 | D12: 750 | E12: 100 | M12: 3 | O12: 2 | P12: 1 | R12: =B12+C12+D12+E12+F12+G12+H12+I12+K12+L12+J12
A13: DUTTA Pinake | B13: 4175 | M13: 15 | R13: =(B13+C13+D13+E13+F13+G13+H13+I13+K13+L13+J13)+(E14+F14+H14+I14)
A15: FAN, Yong (Richard) | C15: 200 | D15: 350 | M15: 2 | R15: =B15+C15+D15+E15+F15+G15+H15+I15+K15+L15+J15
A16: FEIGE, Oliver | R16: =B16+C16+D16+E16+F16+G16+H16+I16+K16+L16+J16
A17: FERNANDES, Delisha | B17: 2200 | L17: 1600 | M17: 15 | R17: =(B17+C17+D17+E17+F17+G17+H17+I17+K17+L17+J17)+(E18+F18+H18+I18)
A19: GAUCHAN Bibek | L19: 3800 | R19: =(B19+C19+D19+E19+F19+G19+H19+I19+K19+L19+J19)+(E20+F20+H20+I20)
A21: GAUCHAN Roshani | B21: 3825 | M21: 15 | R21: =(B21+C21+D21+E21+F21+G21+H21+I21+K21+L21+J21)+(E22+F22+H22+I22)
A23: JAHAN, Nusrat | B23: 1750 | C23: 750 | D23: 750 | F23: 200 | H23: 75 | M23: 3 | Q23: 22.4 | R23: =B23+C23+D23+E23+F23+G23+H23+I23+K23+L23+J23
A24: KC Anisha | B24: 2100 | C24: 800 | D24: 800 | M24: 3 | O24: 2 | P24: 1 | R24: =B24+C24+D24+E24+F24+G24+H24+I24+K24+L24+J24
A25: KCSulav | L25: 3800 | R25: =(B25+C25+D25+E25+F25+G25+H25+I25+K25+L25+J25)+(E26+F26+H26+I26)
A27: KHATRI, Sanjay | B27: 3650 | K27: 150 | M27: 15 | R27: =(B27+C27+D27+E27+F27+G27+H27+I27+K27+L27+J27)+(E28+F28+H28+I28)
A29: MAHMUD M M Ferdous | B29: 3750 | L29: 50 | M29: 15 | R29: =(B29+C29+D29+E29+F29+G29+H29+I29+K29+L29+J29)+(E30+F30+H30+I30)
A31: MAJOHR, Jolie | D31: 500 | F31: 700 | M31: 2 | R31: =B31+C31+D31+E31+F31+G31+H31+I31+K31+L31+J31
A32: MALLA, Kajal | B32: 2050 | C32: 750 | D32: 500 | M32: 3 | Q32: 11.2 | R32: =B32+C32+D32+E32+F32+G32+H32+I32+K32+L32+J32
A33: RAHMAN, Mahinur | R33: =B33+C33+D33+E33+F33+G33+H33+I33+K33+L33
A34: RANA, Royal | B34: 2150 | C34: 500 | M34: 3 | O34: 4 | P34: 2 | R34: =B34+C34+D34+E34+F34+G34+H34+I34+K34+L34+J34
A35: SAHA, Oyndrilla | B35: 1100 | C35: 500 | D35: 750 | M35: 3 | R35: =B35+C35+D35+E35+F35+G35+H35+I35+K35+L35
A36: SAIYED Wasim | B36: 3025 | L36: 775 | M36: 15 | R36: =(B36+C36+D36+E36+F36+G36+H36+I36+K36+L36+J36)+(E37+F37+H37+I37)
A38: SAMIT, Satwat Hossain | B38: 2550 | C38: 500 | D38: 750 | H38: 25 | M38: 3 | R38: =B38+C38+D38+E38+F38+G38+H38+I38+L38+J38+K38
A39: SHIWAKOTI Rojal | B39: 700 | C39: 750 | D39: 1000 | H39: 25 | M39: 3 | N39: 15 | O39: 2 | P39: 1 | Q39: 11.2 | R39: =B39+C39+D39+E39+F39+G39+H39+I39+K39+L39+J39
A40: SHRESTHA, Anish | B40: 1000 | C40: 500 | D40: 500 | E40: 175 | M40: 3 | R40: =B40+C40+D40+E40+F40+G40+H40+I40+K40+L40+J40
A41: SHRESTHA Nikita | B41: 3900 | M41: 15 | R41: =(B41+C41+D41+E41+F41+G41+H41+I41+K41+L41+J41)+(E42+F42+H42+I42)
A43: SHRESTHA Rojan | B43: 4200 | M43: 15 | R43: =(B43+C43+D43+E43+F43+G43+H43+I43+K43+L43+J43)+(E44+F44+H44+I44)
A45: SHRESTHA, Roji | B45: 1000 | C45: 750 | D45: 750 | H45: 100 | M45: 3 | O45: 1 | R45: =B45+C45+D45+E45+F45+G45+H45+I45+K45+L45+J45
A46: TAMANG, Chandraman | C46: 1600 | D46: 600 | F46: 950 | G46: 25 | M46: 3 | O46: 2 | R46: =B46+C46+D46+E46+F46+G46+H46+I46+K46+L46+J46
A47: TAMANG, Prajwol | B47: 950 | C47: 500 | M47: 2 | O47: 1 | R47: =B47+C47+D47+E47+F47+G47+H47+I47+K47+L47+J47
A48: THAPALIYA, Sirish | C48: 1750 | D48: 750 | F48: 650 | M48: 3 | R48: =B48+C48+D48+E48+F48+G48+H48+I48+K48+L48+J48
A49: TIRTHO, Rafid Mahmud | B49: 2000 | C49: 800 | D49: 950 | E49: 150 | G49: 50 | M49: 3 | O49: 6 | P49: 2 | R49: =B49+C49+D49+E49+F49+G49+H49+I49+K49+L49+J49
B50: =SUM(B5:B49) | C50: =SUM(C5:C49) | D50: =SUM(D5:D49) | E50: =SUM(E5:E49) | F50: =SUM(F5:F49) | G50: =SUM(G5:G49) | H50: =SUM(H5:H49) | I50: =SUM(I5:I49) | J50: =SUM(J7:J49) | K50: =SUM(K5:K49) | L50: =SUM(L5:L49) | M50: =SUM(M5:M12,M15:M16,M23:M24,M31:M35,M38:M40,M45:M49)*2.3+(M13+M17+M21+M29+M36+M41+M43+M25+M27+M19) | N50: =SUM(N5:N49) | O50: =SUM(O5:O49) | P50: =SUM(P5:P49) | Q50: =SUM(Q5:Q49) | R50: =SUM(R5:R49)

Sheet Salary Costing Sheet
A1: ='Data Sheet'!B1 | D1: THE ROCKS
K2: HOURLY COSTING | V2: Allowances | Y2: 2.95 | AA2: 4.42 | AB2: 11.2
A3: EMPLOYEE | C3: RATE | D3: 1 | E3: $ | F3: 1.25 | H3: 1.5 | I3: $ | J3: 1.5 | K3: $ | L3: 1.75 | M3: $ | N3: 2 | O3: $ | P3: 2.25 | Q3: $ | R3: Sick | S3: $ | T3: Holiday | U3: $ | V3: Laundry | W3: Superv. | X3: Penalty | Y3: $ | Z3: Penalty | AA3: $ | AB3: Split | AC3: TOTAL | AD3: TOTAL
D4: ORD | F4: SAT | H4: SUN | J4: OT | L4: O/Time | N4: O/Time OR sat milko | P4: P/Hol | R4: Leave | V4: Clothing | W4: P/Hol | X4: 10-12pm | Z4: 12-7am | AB4: Shift | AC4: HOURS | AD4: $'s
A5: DUTTA PINAKE | C5: 31.3 | D5: 22.25 | E5: =C5*D5 | F5: 6.5 | G5: =F5*C5*1.25 | H5: 9 | I5: =C5*1.5*H5 | K5: =C5*1.5*J5 | M5: =C5*1.75*L5 | N5: 4 | O5: =C5*2*N5 | Q5: =C5*2.25*P5 | S5: =C5*R5 | U5: =C5*T5 | V5: 6.9 | W5: 45 | X5: 2 | Y5: =X5*2.95 | Z5: 1 | AA5: =Z5*4.42 | AC5: =D5+F5+H5+J5+L5+N5+P5+R5+T5 | AD5: =E5+G5+I5+K5+M5+O5+Q5+V5+W5+S5+U5+Y5+AA5+AB5
A6: FERNANDES, Delisha | C6: 29.45 | D6: 21.5 | E6: =C6*D6 | F6: 0.5 | G6: =F6*C6*1.25 | I6: =C6*1.5*H6 | K6: =C6*1.5*J6 | M6: =C6*1.75*L6 | O6: =C6*2*N6 | Q6: =C6*2.25*P6 | S6: =C6*R6 | T6: 16 | U6: =C6*T6 | V6: 6.9 | W6: 15 | X6: 6 | Y6: =X6*2.95 | AA6: =Z6*4.42 | AC6: =D6+F6+H6+J6+L6+N6+P6+R6+T6 | AD6: =E6+G6+I6+K6+M6+O6+Q6+V6+W6+S6+U6+Y6+AA6+AB6
A7: GAUCHAN, Bibek | C7: 29.45 | E7: =C7*D7 | G7: =F7*C7*1.25 | I7: =C7*1.5*H7 | K7: =C7*1.5*J7 | M7: =C7*1.75*L7 | O7: =C7*2*N7 | Q7: =C7*2.25*P7 | S7: =C7*R7 | T7: 38 | U7: =C7*T7 | Y7: =X7*2.95 | AA7: =Z7*4.42 | AC7: =D7+F7+H7+J7+L7+N7+P7+R7+T7 | AD7: =E7+G7+I7+K7+M7+O7+Q7+V7+W7+S7+U7+Y7+AA7+AB7
A8: GAUCHAN, Roshani | C8: 29.45 | D8: 32 | E8: =C8*D8 | F8: 6 | G8: =F8*C8*1.25 | I8: =C8*1.5*H8 | J8: 0.25 | K8: =C8*1.5*J8 | M8: =C8*1.75*L8 | O8: =C8*2*N8 | Q8: =C8*2.25*P8 | S8: =C8*R8 | U8: =C8*T8 | V8: 6.9 | Y8: =X8*2.95 | AA8: =Z8*4.42 | AC8: =D8+F8+H8+J8+L8+N8+P8+R8+T8 | AD8: =E8+G8+I8+K8+M8+O8+Q8+V8+W8+S8+U8+Y8+AA8+AB8
A9: KC Sulav | C9: 29.45 | E9: =C9*D9 | G9: =F9*C9*1.25 | I9: =C9*1.5*H9 | K9: =C9*1.5*J9 | M9: =C9*1.75*L9 | O9: =C9*2*N9 | Q9: =C9*2.25*P9 | S9: =C9*R9 | T9: 38 | U9: =C9*T9 | Y9: =X9*2.95 | AA9: =Z9*4.42 | AC9: =D9+F9+H9+J9+L9+N9+P9+R9+T9 | AD9: =E9+G9+I9+K9+M9+O9+Q9+V9+W9+S9+U9+Y9+AA9+AB9
A10: KHATRI, Sanjay | C10: 29.45 | D10: 23.5 | E10: =C10*D10 | F10: 7 | G10: =F10*C10*1.25 | H10: 6 | I10: =C10*1.5*H10 | K10: =C10*1.5*J10 | M10: =C10*1.75*L10 | O10: =C10*2*N10 | Q10: =C10*2.25*P10 | R10: 1.5 | S10: =C10*R10 | U10: =C10*T10 | V10: 6.9 | Y10: =X10*2.95 | AA10: =Z10*4.42 | AC10: =D10+F10+H10+J10+L10+N10+P10+R10+T10 | AD10: =E10+G10+I10+K10+M10+O10+Q10+V10+W10+S10+U10+Y10+AA10+AB10
A11: MAHMUD M M FERDOUS | C11: 29.45 | D11: 22 | E11: =C11*D11 | F11: 7.5 | G11: =F11*C11*1.25 | H11: 8 | I11: =C11*1.5*H11 | K11: =C11*1.5*J11 | M11: =C11*1.75*L11 | O11: =C11*2*N11 | Q11: =C11*2.25*P11 | S11: =C11*R11 | T11: 0.5 | U11: =C11*T11 | V11: 6.9 | Y11: =X11*2.95 | AA11: =Z11*4.42 | AC11: =D11+F11+H11+J11+L11+N11+P11+R11+T11 | AD11: =E11+G11+I11+K11+M11+O11+Q11+V11+W11+S11+U11+Y11+AA11+AB11
A12: SAIYED WASIM | C12: 29.45 | D12: 16 | E12: =C12*D12 | F12: 7.5 | G12: =F12*C12*1.25 | H12: 6.75 | I12: =C12*1.5*H12 | K12: =C12*1.5*J12 | M12: =C12*1.75*L12 | O12: =C12*2*N12 | Q12: =C12*2.25*P12 | S12: =C12*R12 | T12: 7.75 | U12: =C12*T12 | V12: 6.9 | X12: 4 | Y12: =X12*2.95 | Z12: 1 | AA12: =Z12*4.42 | AC12: =D12+F12+H12+J12+L12+N12+P12+R12+T12 | AD12: =E12+G12+I12+K12+M12+O12+Q12+V12+W12+S12+U12+Y12+AA12+AB12
A13: SHRESTHA, Nikita | C13: 29.45 | D13: 24 | E13: =C13*D13 | F13: 8 | G13: =F13*C13*1.25 | H13: 6 | I13: =C13*1.5*H13 | K13: =C13*1.5*J13 | M13: =C13*1.75*L13 | N13: 1 | O13: =C13*2*N13 | Q13: =C13*2.25*P13 | S13: =C13*R13 | U13: =C13*T13 | V13: 6.9 | W13: 45 | X13: 4 | Y13: =X13*2.95 | Z13: 1 | AA13: =Z13*4.42 | AC13: =D13+F13+H13+J13+L13+N13+P13+R13+T13 | AD13: =E13+G13+I13+K13+M13+O13+Q13+V13+W13+S13+U13+Y13+AA13+AB13
A14: SHRESTHA, Rojan | C14: 29.45 | D14: 22 | E14: =C14*D14 | F14: 6.5 | G14: =F14*C14*1.25 | H14: 9.5 | I14: =C14*1.5*H14 | J14: 2 | K14: =C14*1.5*J14 | M14: =C14*1.75*L14 | N14: 2 | O14: =C14*2*N14 | Q14: =C14*2.25*P14 | S14: =C14*R14 | U14: =C14*T14 | V14: 6.9 | X14: 1 | Y14: =X14*2.95 | AA14: =Z14*4.42 | AC14: =D14+F14+H14+J14+L14+N14+P14+R14+T14 | AD14: =E14+G14+I14+K14+M14+O14+Q14+V14+W14+S14+U14+Y14+AA14+AB14
D15: =SUM(D5:D14) | E15: =SUM(E5:E14) | F15: =SUM(F5:F14) | G15: =SUM(G5:G14) | H15: =SUM(H5:H14) | I15: =SUM(I5:I14) | J15: =SUM(J5:J14) | K15: =SUM(K5:K14) | ... AC15: =SUM(AC5:AC14) | AD15: =E15+I15+K15+M15+O15+Q15+V15+W15+S15+U15+Y15+AA15+AB15+G15
AB16: Check - | AC16: =D15+H15+J15+L15+N15+P15+R15+T15+F15 | AD16: =AB15+Y15+AA15+W15+V15+U15+S15+Q15+O15+M15+K15+I15+E15
C35: `

Sheet Proj VS Actual
C6: 42736
B10: 42373 | C10: 42737 | E10: 42380 | F10: 42744 | H10: 42387 | I10: 42751
B11: Last Year | C11: Projected | D11: Actual | E11: Last Year | F11: Projected | G11: Actual | H11: Last Year | I11: Projected | J11: Actual
A12: GROSS TOTAL | B12: 286926.8 | C12: 302722 | D12: 299560 | E12: 197704.39 | F12: 194160 | G12: 210706.33 | H12: 168782.39 | I12: 170258 | J12: 168047.44
A13: NETT TOTAL | B13: =B12/1.1 | C13: =C12/1.1 | D13: =D12/1.1 | E13: =E12/1.1 | F13: =F12/1.1 | G13: =G12/1.1 | H13: =H12/1.1 | I13: =I12/1.1 | J13: =J12/1.1
A14: Customers | B14: 13426 | C14: 12990 | D14: 13376 | E14: 9668 | F14: 9525 | G14: 10184 | H14: 8274 | I14: 8300 | J14: 8007
A15: Average Customer Spend | B15: =B12/B14 | C15: =C12/C14 | D15: =D12/D14 | E15: =E12/E14 | F15: =F12/F14 | G15: =G12/G14 | H15: =H12/H14 | I15: =I12/I14 | J15: =J12/J14
A16: Wage % to Gross total | B16: =(B19*B20)/B12 | C16: =(C19*C20)/C12 | D16: =(D19*D20)/D12 | E16: =(E19*E20)/E12 | F16: =(F19*F20)/F12 | G16: =(G19*G20)/G12 | H16: =(H19*H20)/H12 | I16: =(I19*I20)/I12 | J16: =(J19*J20)/J12
A17: Wage % to Nett Total | B17: =(B19*B20)/B13 | C17: =(C19*C20)/C13 | D17: =(D19*D20)/D13 | E17: =(E19*E20)/E13 | F17: =(F19*F20)/F13 | G17: =(G19*G20)/G13 | H17: =(H19*H20)/H13 | I17: =(I19*I20)/I13 | J17: =(J19*J20)/J13
A18: Productivity | B18: =B14/B20 | C18: =C14/C20 | D18: =D14/D20 | E18: =E14/E20 | F18: =F14/F20 | G18: =G14/G20 | H18: =H14/H20 | I18: =I14/I20 | J18: =J14/J20
A19: Average Hourly Rate | B19: 34.75 | C19: 41 | D19: 41.02 | E19: 30.3 | F19: 30 | G19: 30.7 | H19: 30.22 | I19: 30 | J19: 30.57
A20: Total hours for productivity | B20: 2287.75 | C20: 2223.5 | D20: 2301.5 | E20: 1944.25 | F20: 1729.5 | G20: 1804.25 | H20: 1759 | I20: 1567 | J20: 1685.25
A21: Training Hours used | B21: 0 | C21: 0 | D21: 0 | E21: 39 | F21: 50 | G21: 35 | H21: 0 | I21: 65.5 | J21: 95.5
A22: Number of hours used to cover sick leave | B22: 97.5 | C22: 0 | D22: 8 | E22: 81 | F22: 0 | G22: 36.5 | H22: 26.5 | I22: 0
A23: Minimum HOURS | B23: Kitchen | C23: 656 | E23: Kitchen | F23: 583 | H23: Kitchen | I23: 548
B24: Floor | C24: 1065 | E24: Floor | F24: 1001 | H24: Floor | I24: 926
B25: TOTAL | C25: =SUM(C23:C24) | E25: TOTAL | F25: =SUM(F23:F24) | H25: TOTAL | I25: =SUM(I23:I24)
F27: Details | G27: Hrs | I27: Details | J27: Hrs
F29: Ishita (CO T1-T3) | G29: 15 | I29: Sana (Sup T1-T5) | J29: 37.5
F30: Justas (Host T1-T3) | G30: 15 | I30: Rajesh (Bar T1-T3) | J30: 15
F31: Yuka (Host T1-T3) | G31: 15- CANCELLED | I31: Aga (Bar T1-T3) | J31: 15
F32: Ferdous (Invoice T1) | G32: 5 | I32: Ruta (Host T1-T3) | J32: 15
I33: Yuka (CO T1-T3) | J33: 15- CANCELLED
I34: Ferdous (Inv T2 +f/c) | J34: 13
I35: Total | J35: =SUM(J29:J34)
B36: 42394 | C36: 42758 | E36: 42401 | F36: 42765 | H36: 42408 | I36: 42772
B37: Last Year | C37: Projected | D37: Actual | E37: Last Year | F37: Projected | G37: Actual | H37: Last Year | I37: Projected | J37: Actual
A38: GROSS TOTAL | B38: 178931.17 | C38: 173236 | D38: 179658 | E38: 184512.73 | F38: 216935 | G38: 231891 | H38: 201196.62 | I38: 195285 | J38: 195050.8
A39: NETT TOTAL | B39: =B38/1.1 | C39: =C38/1.1 | D39: =D38/1.1 | E39: =E38/1.1 | F39: =F38/1.1 | G39: =G38/1.1 | H39: =H38/1.1 | I39: =I38/1.1 | J39: =J38/1.1
A40: Customers | B40: 8583 | C40: 8500 | D40: 8502 | E40: 8494 | F40: 9950 | G40: 10209 | H40: 9032 | I40: 8885 | J40: 8542
A41: Average Customer Spend | B41: =B38/B40 | C41: =C38/C40 | D41: =D38/D40 | E41: =E38/E40 | F41: =F38/F40 | G41: =G38/G40 | H41: =H38/H40 | I41: =I38/I40 | J41: =J38/J40
A42: Wage % to Gross total | B42: =(B45*B46)/B38 | C42: =(C45*C46)/C38 | D42: =(D45*D46)/D38 | E42: =(E45*E46)/E38 | F42: =(F45*F46)/F38 | G42: =(G45*G46)/G38 | H42: =(H45*H46)/H38 | I42: =(I45*I46)/I38 | J42: =(J45*J46)/J38
A43: Wage % to Nett Total | B43: =(B45*B46)/B39 | C43: =(C45*C46)/C39 | D43: =(D45*D46)/D39 | E43: =(E45*E46)/E39 | F43: =(F45*F46)/F39 | G43: =(G45*G46)/G39 | H43: =(H45*H46)/H39 | I43: =(I45*I46)/I39 | J43: =(J45*J46)/J39
A44: Productivity | B44: =B40/B46 | C44: =C40/C46 | D44: =D40/D46 | E44: =E40/E46 | F44: =F40/F46 | G44: =G40/G46 | H44: =H40/H46 | I44: =I40/I46 | J44: =J40/J46
A45: Average Hourly Rate | B45: 31.07 | C45: 30 | D45: 30.95 | E45: 35.07 | F45: 35 | G45: 35.06 | H45: 30.34 | I45: 30 | J45: 30.16
A46: Total hours for productivity | B46: 1811.25 | C46: 1664.5 | D46: 1647.25 | E46: 1766.75 | F46: 1810.5 | G46: 1908 | H46: 1720.5 | I46: 1868.5 | J46: 1798.5
A47: Training Hours used | B47: 7.5 | C47: 0 | D47: 45.5 | E47: 48.5 | G47: 89 | H47: 82.5 | I47: 281.5 | J47: 261.5
A48: Number of hours used to cover sick leave | B48: 45 | C48: 0 | E48: 39.5 | H48: 23
A49: Minimum HOURS | B49: Kitchen | C49: 545 | E49: Kitchen | F49: 584 | H49: Kitchen
B50: Floor | C50: 927 | E50: Floor | H50: Floor
...

Sheet Transfers
A1: Transfer OUT to DSQ
A2: EMPLOYEE | C2: RATE | D2: 1 | E2: $ | F2: 1.25 | G2: $ | H2: 1.5 | I2: $ | J2: 1.5 | K2: $ | L2: 1.75 | M2: $ | N2: 2 | O2: $ | P2: 2.25 | R2: 2.5 | T2: split | U2: sup | V2: laundry | X2: 2.95 | Z2: 4.42 | AA2: TOTAL | AB2: TOTAL
F3: SAT | H3: SUN | J3: O/T | L3: O/T | N3: O/T | P3: ph | R3: ph casual | W3: Penalty | X3: $ | Z3: $
A4: MALLA, Kajal | C4: 25.85 | E4: =C4*D4 | G4: =C4*1.25*F4 | I4: =C4*1.5*H4 | K4: =C4*1.5*J4 | M4: =C4*1.75*L4 | O4: =C4*2*N4 | Q4: =C4*2.25*P4 | S4: =C4*2.5*R4 | X4: =W4*X2 | Z4: =Z2*Y4 | AA4: =D4+F4+H4+J4+L4+N4+R4+P4 | AB4: =E4+G4+I4+K4+M4+O4+Z4+X4+V4+T4+Q4+S4+U4
A5: TIRTHO, Rafid Mahmud | C5: 26.7 | E5: =C5*D5 | G5: =F5*C5*F2 | I5: =C5*1.5*H5 | K5: =C5*1.5*J5 | M5: =C5*1.75*L5 | O5: =C5*2*N5 | Q5: =C5*2.25*P5 | S5: =C5*2.5*R5 | X5: =W5*X2 | Z5: =Z2*Y5 | AA5: =D5+F5+H5+J5+L5+N5+R5+P5 | AB5: =E5+G5+I5+K5+M5+O5+Z5+X5+V5+T5+Q5+S5+U5
A6: BANIYA ,Bijusha | B6: CAS | C6: 28.12 | E6: =C6*D6 | G6: =C6*1.25*F6 | I6: =C6*1.5*H6 | K6: =C6*1.5*J6 | M6: =C6*1.75*L6 | O6: =C6*2*N6 | Q6: =C6*2.25*P6 | S6: =C6*2.5*R6 | X6: =W6*X2 | Z6: =Z4*Y6 | AA6: =D6+F6+H6+J6+L6+N6+R6+P6 | AB6: =E6+G6+I6+K6+M6+O6+Z6+X6+V6+T6+Q6+S6+U6
A7: GAUCHAN, Bibek | B7: SAL | C7: 37.45 | E7: =C7*D7 | G7: =C7*1.25*F7 | I7: =C7*1.5*H7 | K7: =C7*1.5*J7 | M7: =C7*1.75*L7 | O7: =C7*2*N7 | Q7: =C7*2.25*P7 | S7: =C7*2.5*R7 | X7: =W7*X5 | Z7: =Z5*Y7 | AA7: =D7+F7+H7+J7+L7+N7+R7+P7 | AB7: =E7+G7+I7+K7+M7+O7+Z7+X7+V7+T7+Q7+S7+U7
A8: KHATRI, Sanjay | B8: SAL | C8: 37.45 | E8: =C8*D8 | G8: =C8*1.25*F8 | I8: =C8*1.5*H8 | K8: =C8*1.5*J8 | M8: =C8*1.75*L8 | O8: =C8*2*N8 | Q8: =C8*2.25*P8 | S8: =C8*2.5*R8 | X8: =W8*X6 | Z8: =Z6*Y8 | AA8: =D8+F8+H8+J8+L8+N8+R8+P8 | AB8: =E8+G8+I8+K8+M8+O8+Z8+X8+V8+T8+Q8+S8+U8
A9: KC Sulav | B9: SAL | C9: 37.45 | E9: =C9*D9 | G9: =C9*1.25*F9 | I9: =C9*1.5*H9 | K9: =C9*1.5*J9 | M9: =C9*1.75*L9 | O9: =C9*2*N9 | Q9: =C9*2.25*P9 | S9: =C9*2.5*R9 | X9: =W9*X6 | Z9: =Z6*Y9 | AA9: =D9+F9+H9+J9+L9+N9+R9+P9 | AB9: =E9+G9+I9+K9+M9+O9+Z9+X9+V9+T9+Q9+S9+U9
A10: SHIWAKOTI, Rojal | B10: SUP | C10: 28.5 | E10: =C10*D10 | G10: =C10*1.25*F10 | I10: =C10*1.5*H10 | K10: =C10*1.5*J10 | M10: =C10*1.75*L10 | O10: =C10*2*N10 | Q10: =C10*2.25*P10 | S10: =C10*2.5*R10 | X10: =W10*X7 | Z10: =Z7*Y10 | AA10: =D10+F10+H10+J10+L10+N10+R10+P10 | AB10: =E10+G10+I10+K10+M10+O10+Z10+X10+V10+T10+Q10+S10+U10
A11: FAN, Yong (Richard) | B11: CAS | C11: 29.45 | E11: =C11*D11 | G11: =C11*1.25*F11 | H11: 3.5 | I11: =C11*1.5*H11 | K11: =C11*1.5*J11 | M11: =C11*1.75*L11 | O11: =C11*2*N11 | Q11: =C11*2.25*P11 | S11: =C11*2.5*R11 | X11: =W11*X9 | Z11: =Z9*Y11 | AA11: =D11+F11+H11+J11+L11+N11+R11+P11 | AB11: =E11+G11+I11+K11+M11+O11+Z11+X11+V11+T11+Q11+S11+U11
AA12: =SUM(AA4:AA11) | AB12: =SUM(AB4:AB11)
A13: transfer OUT to BH
A14: EMPLOYEE | C14: RATE | D14: 1 | E14: $ | F14: 1.25 | G14: $ | H14: 1.5 | I14: $ | J14: 1.5 | K14: $ | L14: 1.75 | M14: $ | N14: 2 | O14: $ | P14: 2.25 | R14: 2.5 | T14: split | U14: sup | V14: laundry | W14: 10-12am | X14: 2.81 | Z14: 4.22 | AA14: TOTAL | AB14: TOTAL
F15: SAT | H15: SUN | J15: O/T | L15: O/T | N15: O/T
A16: KC, Sulav | B16: SAL | C16: 37.45 | E16: =C16*D16 | G16: =E16*F16 | I16: =C16*1.5*H16 | K16: =E16*1.5*J16 | M16: =C16*1.75*L16 | O16: =E16*1.75*N16 | Q16: =E16*2.25*P16 | S16: =C16*2.5*R16 | X16: =W16*X14 | Z16: =Y16*Z14 | AA16: =D16+P16+R16+F16+H16+J16+L16+N16 | AB16: =E16+G16+I16+K16+M16+O16+Z16+X16+V16+Q16+S16+T16+U16
A17: Khanal, Nischal | C17: 28.12 | E17: =C17*D17 | G17: =E17*F17 | I17: =C17*1.5*H17 | K17: =E17*1.5*J17 | M17: =C17*1.75*L17 | O17: =E17*1.75*N17 | Q17: =E17*2.25*P17 | S17: =C17*2.5*R17 | X17: =W17*X15 | Z17: =Y17*Z15 | AA17: =D17+P17+R17+F17+H17+J17+L17+N17 | AB17: =E17+G17+I17+K17+M17+O17+Z17+X17+V17+Q17+S17+T17+U17
A18: SHIWAKOTI, Rojal | C18: 28.5 | E18: =C18*D18 | G18: =C18*1.25*F18 | I18: =C18*1.5*H18 | K18: =C18*1.5*J18 | M18: =C18*1.75*L18 | O18: =C18*2*N18 | Q18: =C18*2.25*P18 | S18: =C18*2.5*R18 | X18: =W18*X12 | Z18: =Y18*Z11 | AA18: =D18+P18+R18+F18+H18+J18+L18+N18 | AB18: =E18+G18+I18+K18+M18+O18+Z18+X18+V18+Q18+S18+T18+U18
A19: MAJOHR, Jolie | C19: 25.85 | E19: =C19*D19 | G19: =C19*1.25*F19 | I19: =C19*1.5*H19 | K19: =C19*1.5*J19 | M19: =C19*1.75*L19 | O19: =C19*2*N19 | Q19: =C19*2.25*P19 | S19: =C19*2.5*R19 | X19: =W19*X12 | Z19: =Y19*Z11 | AA19: =D19+P19+R19+F19+H19+J19+L19+N19 | AB19: =E19+G19+I19+K19+M19+O19+Z19+X19+V19+Q19+S19+T19+U19
A20: RAHMAN, Mahinur | C20: 25.85 | E20: =C20*D20 | G20: =C20*1.25*F20 | I20: =C20*1.5*H20 | K20: =C20*1.5*J20 | M20: =C20*1.75*L20 | O20: =C20*2*N20 | Q20: =C20*2.25*P20 | S20: =C20*2.5*R20 | X20: =W20*X13 | Z20: =Y20*Z12 | AA20: =D20+P20+R20+F20+H20+J20+L20+N20 | AB20: =E20+G20+I20+K20+M20+O20+Z20+X20+V20+Q20+S20+T20+U20
A21: DISSANAYAKE, Dissanayake Mudiyanselage Hansali Nimsadi | B21: CAS | C21: 25.85 | E21: =C21*D21 | G21: =C21*1.25*F21 | I21: =C21*1.5*H21 | K21: =C21*1.5*J21 | M21: =C21*1.75*L21 | O21: =C21*2*N21 | Q21: =C21*2.25*P21 | S21: =C21*2.5*R21 | X21: =W21*X14 | Z21: =Y21*Z13 | AA21: =D21+P21+R21+F21+H21+J21+L21+N21 | AB21: =E21+G21+I21+K21+M21+O21+Z21+X21+V21+Q21+S21+T21+U21
C22: 26.7 | E22: =C22*D22 | G22: =C22*1.25*F22 | I22: =C22*1.5*H22 | K22: =C22*1.5*J22 | M22: =C22*1.75*L22 | O22: =C22*2*N22 | Q22: =C22*2.25*P22 | S22: =C22*2.5*R22 | X22: =W22*X15 | Z22: =Y22*Z14 | AA22: =D22+P22+R22+F22+H22+J22+L22+N22 | AB22: =E22+G22+I22+K22+M22+O22+Z22+X22+V22+Q22+S22+T22+U22
AA23: =SUM(AA16:AA22) | AB23: =SUM(AB16:AB22)
A24: Transfer OUT to Northmead
A25: EMPLOYEE | C25: RATE | D25: 1 | E25: $ | F25: 1.25 | G25: $ | H25: 1.5 | I25: $ | J25: 1.5 | K25: $ | L25: 1.75 | M25: $ | N25: 2 | O25: $ | P25: 2.25 | R25: 2.5 | T25: split | U25: sup | V25: laundry | X25: 2.48 | Z25: 3.71 | AA25: TOTAL | AB25: TOTAL
F26: SAT | H26: SUN | J26: O/T | L26: O/T | N26: O/T | P26: ph | R26: ph casual
E27: =C27*D27 | G27: =C27*1.25*F27 | I27: =C27*1.5*H27 | K27: =C27*1.5*J27 | M27: =C27*1.75*L27 | O27: =C27*2*N27 | Q27: =C27*2.25*P27 | S27: =C27*2.5*R27 | X27: =W27*X25 | Z27: =Y27*Z25 | AA27: =D27+F27+H27+J27+L27+N27 | AB27: =E27+G27+I27+K27+M27+O27+Z27+X27+V27+T27+Q27+S27
A28: WAGLE KHATRI, Sabina | C28: 26.7 | E28: =C28*D28 | G28: =C28*1.25*F28 | I28: =C28*1.5*H28 | K28: =C28*1.5*J28 | M28: =C28*1.75*L28 | O28: =C28*2*N28 | Q28: =C28*2.25*P28 | S28: =C28*2.5*R28 | X28: =W28*X25 | Z28: =Y28*Z25 | AA28: =D28+F28+H28+J28+L28+N28+P28 | AB28: =E28+G28+I28+K28+M28+O28+Z28+X28+V28+T28+Q28+S28
A29: PARTHO, Razin Mahmud | C29: 27.17 | E29: =C29*D29 | G29: =C29*1.25*F29 | I29: =C29*1.5*H29 | K29: =C29*1.5*J29 | M29: =C29*1.75*L29 | O29: =C29*2*N29 | Q29: =C29*2.25*P29 | S29: =C29*2.5*R29 | X29: =W29*X25 | Z29: =Y29*Z25 | AA29: =D29+F29+H29+J29+L29+N29 | AB29: =E29+G29+I29+K29+M29+O29+Z29+X29+V29+T29+Q29+S29
A30: KARTA, Vera | C30: 40 | E30: =C30*D30 | G30: =C30*1.25*F30 | I30: =C30*1.5*H30 | K30: =C30*1.5*J30 | M30: =C30*1.75*L30 | O30: =C30*2*N30 | Q30: =C30*2.25*P30 | S30: =C30*2.5*R30 | X30: =W30*X25 | Z30: =Y30*Z25 | AA30: =D30+F30+H30+J30+L30+N30 | AB30: =E30+G30+I30+K30+M30+O30+Z30+X30+V30+T30+Q30+S30
A31: Feige, Oliver | B31: cas | C31: 15.51 | E31: =C31*D31 | G31: =C31*1.25*F31 | I31: =C31*1.5*H31 | K31: =C31*1.5*J31 | M31: =C31*1.75*L31 | O31: =C31*2*N31 | Q31: =C31*2.25*P31 | S31: =C31*2.5*R31 | X31: =W31*X25 | Z31: =Y31*Z25 | AA31: =D31+F31+H31+J31+L31+N31 | AB31: =E31+G31+I31+K31+M31+O31+Z31+X31+V31+T31+Q31+S31
I32: =C32*1.5*H32 | Q32: =C32*2.25*P32 | X32: =W32*X25
AA33: =SUM(AA27:AA31) | AB33: =SUM(AB27:AB31)
A34: Transfer IN from DSQ
A35: EMPLOYEE | C35: RATE | D35: 1 | E35: $ | F35: 1.25 | G35: $ | H35: 1.5 | I35: $ | J35: 1.5 | K35: $ | L35: 1.75 | M35: $ | N35: 2 | O35: $ | P35: 2.25 | R35: Sick | S35: $ | T35: split | U35: sup | V35: laundry | X35: 2.95 | Z35: 4.42 | AA35: TOTAL | AB35: TOTAL
F36: SAT | H36: SUN | J36: O/T | L36: O/T | N36: O/T | P36: PH
A37: KHANAL, Nischal | C37: 29.45 | D37: 21.5 | E37: =C37*D37 | F37: 6.5 | G37: =C37*1.25*F37 | H37: 8.5 | I37: =C37*1.5*H37 | K37: =C37*1.5*J37 | M37: =C37*1.75*L37 | N37: 0.25 | O37: =C37*2*N37 | S37: =R37*C37 | V37: 6.9 | W37: 6 | X37: =W37*X35 | Y37: 3 | Z37: =Y37*Z35 | AA37: =D37+F37+H37+J37+L37+N37+P37+R37 | AB37: =E37+G37+I37+K37+M37+O37+Z37+X37+V37+T37+R37+Q37
A38: GODA, Yuka | B38: SAL | C38: 40.5 | E38: =C38*D38 | G38: =C38*1.25*F38 | I38: =C38*1.5*H38 | K38: =C38*1.5*J38 | M38: =C38*1.75*L38 | O38: =C38*2*N38 | X38: =W38*X35 | Z38: =Y38*Z35 | AA38: =D38+F38+H38+J38+L38+N38 | AB38: =E38+G38+I38+K38+M38+O38+Z38+X38+V38+T38
A39: MANANDHAR, Leelen | C39: 26.7 | E39: =C39*D39 | G39: =C39*1.25*F39 | I39: =C39*1.5*H39 | K39: =C39*1.5*J39 | M39: =C39*1.75*L39 | O39: =C39*2*N39 | X39: =W39*X35 | Z39: =Y39*Z35 | AA39: =D39+F39+H39+J39+L39+N39 | AB39: =E39+G39+I39+K39+M39+O39+Z39+X39+V39+T39
A40: ISKANDAR, Kenny | C40: 28.12 | E40: =C40*D40 | G40: =C40*1.25*F40 | I40: =C40*1.5*H40 | K40: =C40*1.5*J40 | M40: =C40*1.75*L40 | O40: =C40*2*N40 | X40: =W40*X35 | Z40: =Y40*Z35 | AA40: =D40+F40+H40+J40+L40+N40 | AB40: =E40+G40+I40+K40+M40+O40+Z40+X40+V40+T40
...
